from fastapi import Depends, HTTPException, status, Depends
from sqlalchemy.orm import Session
from fastapi.security import OAuth2PasswordBearer
from datetime import timedelta, datetime
from typing import Optional
from jose import JWTError, jwt

from .. import schemas, database, models

# used by the function get_curret_user 
oauth2_scheme = OAuth2PasswordBearer(tokenUrl="login")

SECRET_KEY = "09d25e094faa6ca2556c818166b7a9563b93f7099f6f0f4caa6cf63b88e8d3e7"
ALGORITHM = "HS256"
ACCESS_TOKEN_EXPIRE_MINUTES = 45


def create_access_token(data: dict, expires_delta: Optional[timedelta] = None):
    to_encode = data.copy()
    if expires_delta:
        expire = datetime.utcnow() + expires_delta
    else:
        expire = datetime.utcnow() + timedelta(minutes=ACCESS_TOKEN_EXPIRE_MINUTES)
    to_encode.update({"exp": expire})
    encoded_jwt = jwt.encode(to_encode, SECRET_KEY, algorithm=ALGORITHM)
    return encoded_jwt


def verify_access_token(token, credentials_exception):
    '''
    Function used by a get_current_user located in this file.
    Parameter(2nd)- credentials_exception is an HTTPException
                    declared inside get_current_user function.
    '''
    try:
        payload = jwt.decode(token, SECRET_KEY, algorithms=[ALGORITHM])
        id: int = payload.get("user_id")
        if id is None:
            raise credentials_exception
        token_data = schemas.TokenData(id=id)
    except JWTError:
        raise credentials_exception
    
    return token_data


def get_current_user(token: str = Depends(oauth2_scheme), db: Session = Depends(database.get_db)):
    credentials_exception = HTTPException(
        status_code=status.HTTP_401_UNAUTHORIZED,
        detail="Could not validate credentials",
        headers={"WWW-Authenticate": "Bearer"},
    )

    token_data = verify_access_token(token, credentials_exception)
    current_user = db.query(models.User).filter(models.User.id == token_data.id).first()

    return current_user

